<?xml version="1.0" encoding="utf-8"?>
<!-- This URDF was automatically created by SolidWorks to URDF Exporter! Originally created by Stephen Brawner (brawner@gmail.com) 
     Commit Version: 1.6.0-1-g15f4949  Build Version: 1.6.7594.29634
     For more information, please see http://wiki.ros.org/sw_urdf_exporter -->
<robot
  name="wheel_chair_robot">
  
  <link
    name="base_footprint">
    <inertial>
      <origin
        xyz="5.41034890439227E-20 2.2865873310991E-18 -0.0353753976311337"
        rpy="0 0 0" />
      <mass
        value="7.09200000000001E-05" />
      <inertia
        ixx="2.93340926097869E-08"
        ixy="-3.85037082822614E-27"
        ixz="3.60459939671844E-27"
        iyy="2.93340926097869E-08"
        iyz="1.84769596144008E-24"
        izz="1.382E-11" />
    </inertial>
    <visual>
      <origin
        xyz="0 0 0"
        rpy="0 0 0" />
      <geometry>
        <mesh
          filename="package://wheel_chair_robot/meshes/base_for_print_link.STL" />
      </geometry>
      <material
        name="">
        <color
          rgba="0.792156862745098 0.819607843137255 0.933333333333333 1" />
      </material>
    </visual>
    <collision>
      <origin
        xyz="0 0 0"
        rpy="0 0 0" />
      <geometry>
        <mesh
          filename="package://wheel_chair_robot/meshes/base_for_print_link.STL" />
      </geometry>
    </collision>
  </link>
  <link
    name="base_link">
    <inertial>
      <origin
        xyz="-0.000183927413758982 0.122740439529099 -0.0288849781882508"
        rpy="0 0 0" />
      <mass
        value="0.471290238762329" />
      <inertia
        ixx="0.000718160491232769"
        ixy="6.15110268523059E-10"
        ixz="-1.16572820178802E-08"
        iyy="0.00133061138183249"
        iyz="1.38556065851481E-07"
        izz="0.000639912786707179" />
    </inertial>
    <visual>
      <origin
        xyz="0 0 0"
        rpy="0 0 0" />
      <geometry>
        <mesh
          filename="package://wheel_chair_robot/meshes/base_link.STL" />
      </geometry>
      <material
        name="">
        <color
          rgba="0.792156862745098 0.819607843137255 0.933333333333333 1" />
      </material>
    </visual>
    <collision>
      <origin
        xyz="0 0 0"
        rpy="0 0 0" />
      <geometry>
        <mesh
          filename="package://wheel_chair_robot/meshes/base_link.STL" />
      </geometry>
    </collision>
  </link>
  <joint
    name="base_joint"
    type="fixed">
    <origin
      xyz="0 0 0"
      rpy="0 0 0" />
    <parent
      link="base_footprint" />
    <child
      link="base_link" />
    <axis
      xyz="0 0 0" />
  </joint>
  <link
    name="wheel_L_link">
    <inertial>
      <origin
        xyz="-0.016617 -8.7963E-12 -7.3698E-07"
        rpy="0 0 0" />
      <mass
        value="0.053158" />
      <inertia
        ixx="4.0958E-05"
        ixy="3.054E-15"
        ixz="2.443E-10"
        iyy="2.3293E-05"
        iyz="5.1359E-16"
        izz="2.3293E-05" />
    </inertial>
    <visual>
      <origin
        xyz="0 0 0"
        rpy="0 0 0" />
      <geometry>
        <mesh
          filename="package://wheel_chair_robot/meshes/wheel_L_link.STL" />
      </geometry>
      <material
        name="">
        <color
          rgba="0 0 0 1" />
      </material>
    </visual>
    <collision>
      <origin
        xyz="0 0 0"
        rpy="0 0 0" />
      <geometry>
        <mesh
          filename="package://wheel_chair_robot/meshes/wheel_L_link.STL" />
      </geometry>
    </collision>
  </link>
  <joint
    name="wheel_L_joint"
    type="continuous">
    <origin
      xyz="-0.0669 0 0.033497"
      rpy="3.1416 0 0" />
    <parent
      link="base_link" />
    <child
      link="wheel_L_link" />
    <axis
      xyz="1 0 0" />
  </joint>
  <link
    name="wheel_R_link">
    <inertial>
      <origin
        xyz="-0.016617 -8.7964E-12 -7.3698E-07"
        rpy="0 0 0" />
      <mass
        value="0.053158" />
      <inertia
        ixx="4.0958E-05"
        ixy="3.054E-15"
        ixz="2.443E-10"
        iyy="2.3293E-05"
        iyz="5.1359E-16"
        izz="2.3293E-05" />
    </inertial>
    <visual>
      <origin
        xyz="0 0 0"
        rpy="0 0 0" />
      <geometry>
        <mesh
          filename="package://wheel_chair_robot/meshes/wheel_R_link.STL" />
      </geometry>
      <material
        name="">
        <color
          rgba="0 0 0 1" />
      </material>
    </visual>
    <collision>
      <origin
        xyz="0 0 0"
        rpy="0 0 0" />
      <geometry>
        <mesh
          filename="package://wheel_chair_robot/meshes/wheel_R_link.STL" />
      </geometry>
    </collision>
  </link>
  <joint
    name="wheel_R_joint"
    type="continuous">
    <origin
      xyz="0.0669 0 0.033497"
      rpy="1.5708 0 3.1416" />
    <parent
      link="base_link" />
    <child
      link="wheel_R_link" />
    <axis
      xyz="1 0 0" />
  </joint>
  <link
    name="lidar_link">
    <inertial>
      <origin
        xyz="-4.3368E-19 0 0.016956"
        rpy="0 0 0" />
      <mass
        value="0.090366" />
      <inertia
        ixx="2.9262E-05"
        ixy="-9.893E-38"
        ixz="-2.6866E-21"
        iyy="2.9262E-05"
        iyz="3.4542E-21"
        izz="4.6984E-05" />
    </inertial>
    <visual>
      <origin
        xyz="0 0 0"
        rpy="0 0 0" />
      <geometry>
        <mesh
          filename="package://wheel_chair_robot/meshes/lidar_link.STL" />
      </geometry>
      <material
        name="">
        <color
          rgba="0 0 1 1" />
      </material>
    </visual>
    <collision>
      <origin
        xyz="0 0 0"
        rpy="0 0 0" />
      <geometry>
        <mesh
          filename="package://wheel_chair_robot/meshes/lidar_link.STL" />
      </geometry>
    </collision>
  </link>
  <joint
    name="lidar_joint"
    type="fixed">
    <origin
      xyz="-0.002 0.079323 0.20826"
      rpy="0 0 0" />
    <parent
      link="base_link" />
    <child
      link="lidar_link" />
    <axis
      xyz="0 0 1" />
  </joint>
  <link
    name="imu_link">
    <inertial>
      <origin
        xyz="-2.6256E-17 0 0.000865"
        rpy="0 0 0" />
      <mass
        value="0.00066052" />
      <inertia
        ixx="2.8402E-08"
        ixy="4.3419E-24"
        ixz="5.2242E-25"
        iyy="1.6689E-08"
        iyz="-5.5152E-26"
        izz="4.4761E-08" />
    </inertial>
    <visual>
      <origin
        xyz="0 0 0"
        rpy="0 0 0" />
      <geometry>
        <mesh
          filename="package://wheel_chair_robot/meshes/imu_link.STL" />
      </geometry>
      <material
        name="">
        <color
          rgba="1 0 0 1" />
      </material>
    </visual>
    <collision>
      <origin
        xyz="0 0 0"
        rpy="0 0 0" />
      <geometry>
        <mesh
          filename="package://wheel_chair_robot/meshes/imu_link.STL" />
      </geometry>
    </collision>
  </link>
  <joint
    name="imu_joint"
    type="fixed">
    <origin
      xyz="0 0.14042 0.14476"
      rpy="0 0 0" />
    <parent
      link="base_link" />
    <child
      link="imu_link" />
    <axis
      xyz="0 0 0" />
  </joint>
  <link
    name="caster_link">
    <inertial>
      <origin
        xyz="-1.38777878078145E-17 1.73472347597681E-18 -2.36309788418562E-16"
        rpy="0 0 0" />
      <mass
        value="0.00573786372737865" />
      <inertia
        ixx="3.01346626020544E-07"
        ixy="2.97608581872277E-42"
        ixz="1.83836420325763E-22"
        iyy="3.01346626020544E-07"
        iyz="1.95301445843342E-39"
        izz="4.48449911942938E-07" />
    </inertial>
    <visual>
      <origin
        xyz="0 0 0"
        rpy="0 0 0" />
      <geometry>
        <mesh
          filename="package://wheel_chair_robot/meshes/caster_link.STL" />
      </geometry>
      <material
        name="">
        <color
          rgba="0.792156862745098 0.819607843137255 0.933333333333333 1" />
      </material>
    </visual>
    <collision>
      <origin
        xyz="0 0 0"
        rpy="0 0 0" />
      <geometry>
        <mesh
          filename="package://wheel_chair_robot/meshes/caster_link.STL" />
      </geometry>
    </collision>
  </link>
  <joint
    name="caster_joint"
    type="fixed">
    <origin
      xyz="0 0.082473 0.01224"
      rpy="1.5708 0 1.5708" />
    <parent
      link="base_link" />
    <child
      link="caster_link" />
    <axis
      xyz="0 0 1" />
  </joint>
</robot>
